<?xml version="1.0"?>
<robot xmlns:xacro="http://www.ros.org/wiki/xacro" name="four_wheel_robot">

  <!-- ===== Constants / Properties ===== -->
  <xacro:property name="base_length"  value="0.50"/>
  <xacro:property name="base_width"   value="0.30"/>
  <xacro:property name="base_height"  value="0.15"/>
  <xacro:property name="base_mass"    value="5.0"/>

  <xacro:property name="wheel_radius" value="0.10"/>
  <xacro:property name="wheel_width"  value="0.05"/>
  <xacro:property name="wheel_mass"   value="0.5"/>

  <!-- Wheel x offset from base centre (half base length - small margin) -->
  <xacro:property name="wheel_x_offset" value="0.18"/>
  <!-- Wheel y offset from base centre (half base width + half wheel width) -->
  <xacro:property name="wheel_y_offset" value="0.175"/>
  <!-- Wheel sits on the ground: centre height = wheel_radius -->
  <xacro:property name="wheel_z_offset" value="-0.025"/>

  <!-- ===== Inertia macros ===== -->
  <xacro:macro name="box_inertia" params="m l w h">
    <inertial>
      <mass value="${m}"/>
      <inertia
        ixx="${m*(w*w+h*h)/12}" ixy="0" ixz="0"
        iyy="${m*(l*l+h*h)/12}" iyz="0"
        izz="${m*(l*l+w*w)/12}"/>
    </inertial>
  </xacro:macro>

  <xacro:macro name="cylinder_inertia" params="m r h">
    <inertial>
      <mass value="${m}"/>
      <inertia
        ixx="${m*(3*r*r+h*h)/12}" ixy="0" ixz="0"
        iyy="${m*(3*r*r+h*h)/12}" iyz="0"
        izz="${m*r*r/2}"/>
    </inertial>
  </xacro:macro>

  <xacro:macro name="sphere_inertia" params="m r">
    <inertial>
      <mass value="${m}"/>
      <inertia
        ixx="${2*m*r*r/5}" ixy="0" ixz="0"
        iyy="${2*m*r*r/5}" iyz="0"
        izz="${2*m*r*r/5}"/>
    </inertial>
  </xacro:macro>

  <!-- ===== Wheel macro ===== -->
  <!--
    prefix : fl | fr | rl | rr
    x_sign :  1 (front) | -1 (rear)
    y_sign :  1 (left)  | -1 (right)
  -->
  <xacro:macro name="wheel" params="prefix x_sign y_sign">
    <link name="${prefix}_wheel_link">
      <visual>
        <origin xyz="0 0 0" rpy="${pi/2} 0 0"/>
        <geometry>
          <cylinder radius="${wheel_radius}" length="${wheel_width}"/>
        </geometry>
        <material name="dark_grey">
          <color rgba="0.2 0.2 0.2 1.0"/>
        </material>
      </visual>
      <collision>
        <origin xyz="0 0 0" rpy="${pi/2} 0 0"/>
        <geometry>
          <cylinder radius="${wheel_radius}" length="${wheel_width}"/>
        </geometry>
      </collision>
      <xacro:cylinder_inertia m="${wheel_mass}" r="${wheel_radius}" h="${wheel_width}"/>
    </link>

    <joint name="${prefix}_wheel_joint" type="continuous">
      <parent link="base_link"/>
      <child  link="${prefix}_wheel_link"/>
      <origin xyz="${x_sign*wheel_x_offset} ${y_sign*wheel_y_offset} ${wheel_z_offset}"
              rpy="0 0 0"/>
      <axis xyz="0 1 0"/>
      <dynamics damping="0.1" friction="0.1"/>
      <limit effort="10.0" velocity="5.0"/>
    </joint>
  </xacro:macro>

  <!-- ===== base_footprint ===== -->
  <link name="base_footprint"/>

  <joint name="base_footprint_joint" type="fixed">
    <parent link="base_footprint"/>
    <child  link="base_link"/>
    <origin xyz="0 0 ${wheel_radius}" rpy="0 0 0"/>
  </joint>

  <!-- ===== Base link ===== -->
  <link name="base_link">
    <visual>
      <origin xyz="0 0 0" rpy="0 0 0"/>
      <geometry>
        <box size="${base_length} ${base_width} ${base_height}"/>
      </geometry>
      <material name="blue">
        <color rgba="0.2 0.4 0.8 1.0"/>
      </material>
    </visual>
    <collision>
      <origin xyz="0 0 0" rpy="0 0 0"/>
      <geometry>
        <box size="${base_length} ${base_width} ${base_height}"/>
      </geometry>
    </collision>
    <xacro:box_inertia m="${base_mass}" l="${base_length}" w="${base_width}" h="${base_height}"/>
  </link>

  <!-- ===== Wheels ===== -->
  <xacro:wheel prefix="fl" x_sign=" 1" y_sign=" 1"/>
  <xacro:wheel prefix="fr" x_sign=" 1" y_sign="-1"/>
  <xacro:wheel prefix="rl" x_sign="-1" y_sign=" 1"/>
  <xacro:wheel prefix="rr" x_sign="-1" y_sign="-1"/>

  <!-- ===== Laser scanner ===== -->
  <link name="lidar_link">
    <visual>
      <origin xyz="0 0 0" rpy="0 0 0"/>
      <geometry>
        <cylinder radius="0.04" length="0.06"/>
      </geometry>
      <material name="black">
        <color rgba="0.1 0.1 0.1 1.0"/>
      </material>
    </visual>
    <collision>
      <origin xyz="0 0 0" rpy="0 0 0"/>
      <geometry>
        <cylinder radius="0.04" length="0.06"/>
      </geometry>
    </collision>
    <xacro:cylinder_inertia m="0.1" r="0.04" h="0.06"/>
  </link>

  <joint name="lidar_joint" type="fixed">
    <parent link="base_link"/>
    <child  link="lidar_link"/>
    <origin xyz="0.0 0.0 ${base_height/2 + 0.03}" rpy="0 0 0"/>
  </joint>

  <!-- ===== Camera ===== -->
  <link name="camera_link">
    <visual>
      <origin xyz="0 0 0" rpy="0 0 0"/>
      <geometry>
        <box size="0.04 0.08 0.04"/>
      </geometry>
      <material name="red">
        <color rgba="0.8 0.1 0.1 1.0"/>
      </material>
    </visual>
    <collision>
      <origin xyz="0 0 0" rpy="0 0 0"/>
      <geometry>
        <box size="0.04 0.08 0.04"/>
      </geometry>
    </collision>
    <xacro:box_inertia m="0.05" l="0.04" w="0.08" h="0.04"/>
  </link>

  <joint name="camera_joint" type="fixed">
    <parent link="base_link"/>
    <child  link="camera_link"/>
    <origin xyz="${base_length/2 - 0.01} 0.0 ${base_height/2 - 0.01}" rpy="0 0 0"/>
  </joint>

  <!-- Camera optical frame (Z forward, X right, Y down) -->
  <link name="camera_optical_link"/>
  <joint name="camera_optical_joint" type="fixed">
    <parent link="camera_link"/>
    <child  link="camera_optical_link"/>
    <origin xyz="0 0 0" rpy="${-pi/2} 0 ${-pi/2}"/>
  </joint>

  <!-- ===== IMU ===== -->
  <link name="imu_link">
    <visual>
      <origin xyz="0 0 0" rpy="0 0 0"/>
      <geometry>
        <box size="0.03 0.03 0.01"/>
      </geometry>
      <material name="green">
        <color rgba="0.1 0.8 0.1 1.0"/>
      </material>
    </visual>
    <collision>
      <origin xyz="0 0 0" rpy="0 0 0"/>
      <geometry>
        <box size="0.03 0.03 0.01"/>
      </geometry>
    </collision>
    <xacro:box_inertia m="0.01" l="0.03" w="0.03" h="0.01"/>
  </link>

  <joint name="imu_joint" type="fixed">
    <parent link="base_link"/>
    <child  link="imu_link"/>
    <origin xyz="0.0 0.0 0.0" rpy="0 0 0"/>
  </joint>

  <!-- Include Gazebo-specific elements -->
  <xacro:include filename="$(find nav2)/urdf/gazebo.xacro"/>

</robot>
